<?xml version="1.0" ?>
<robot name="materials">
    <!-- Define materials -->
    <material name="color_1">
        <color rgba="0.173 0.231 0.349 1" />
    </material>
    <material name="color_2">
        <color rgba="0.318 0.137 0.255 1" />
    </material>
    <material name="color_3">
        <color rgba="0.839 0.678 0.773 1" />
    </material>
    <material name="color_4">
        <color rgba="0.953 0.737 1.0 1" />
    </material>
    <material name="color_5">
        <color rgba="0.749 0.765 0.788 1" />
    </material>
    <material name="color_6">
        <color rgba="0.91 0.49 0.839 1" />
    </material>
    <material name="color_7">
        <color rgba="0.373 0.451 0.957 1" />
    </material>
    <material name="color_8">
        <color rgba="0.318 0.337 0.051 1" />
    </material>
    <!-- Define robot -->
    <!-- Base -->
    <link name="base_link">
        <visual>
            <geometry>
                <box size="4.0 4.0 0.5" />
            </geometry>
            <origin rpy="0 0 0" xyz="0 0 -0.25" />
            <material name="color_1" />
        </visual>
    </link>
    <!-- Arm 1 -->
    <link name="arm_1">
        <visual>
            <geometry>
                <box size="0.2 0.2 0.4" />
            </geometry>
            <origin rpy="0 0 0" xyz="0 0 0.2" />
            <material name="color_3" />
        </visual>
    </link>
    <!-- Arm 2 -->
    <link name="arm_2">
        <visual>
            <geometry>
                <box size="0.2 0.2 1.0" />
            </geometry>
            <origin rpy="0 0 0" xyz="0.1 0 0.4" />
            <material name="color_5" />
        </visual>
    </link>
    <!-- Arm 3 -->
    <link name="arm_3">
        <visual>
            <geometry>
                <box size="0.2 0.2 1.0" />
            </geometry>
            <origin rpy="0 0 0" xyz="0.1 0 0.4" />
            <material name="color_7" />
        </visual>
    </link>
    <!-- Arm 4 5 6 -->
    <link name="arm_4" />
    <link name="arm_5" />
    <link name="arm_6">
        <visual>
            <geometry>
                <sphere radius="0.1" />
            </geometry>
            <origin rpy="0 0 0" xyz="0 0 0" />
            <material name="color_2" />
        </visual>
    </link>
    <!-- End effector -->
    <link name="end_effector">
        <visual>
            <geometry>
                <cylinder length="0.4" radius="0.01" />
            </geometry>
            <origin rpy="0 0 0" xyz="0 0 0.2" />
            <material name="color_4" />
        </visual>
    </link>
    <!-- Define joints -->
    <joint name="base_to_its_part_1" type="revolute">
        <parent link="base_link" />
        <child link="arm_1" />
        <origin rpy="0 0 0" xyz="0 0 0" />
        <axis xyz="0 0 1" />
        <limit effort="20" lower="-6.28" upper="6.28" velocity="1.57" />
    </joint>
    <joint name="arm_1_to_arm_2" type="revolute">
        <parent link="arm_1" />
        <child link="arm_2" />
        <origin rpy="0 0 0" xyz="0.1 0 0.3" />
        <axis xyz="1 0 0" />
        <limit effort="20" lower="-6.28" upper="6.28" velocity="1.57" />
    </joint>
    <joint name="arm_2_to_arm_3" type="revolute">
        <parent link="arm_2" />
        <child link="arm_3" />
        <origin rpy="0 0 0" xyz="0.2 0 0.8" />
        <axis xyz="1 0 0" />
        <limit effort="20" lower="-6.28" upper="6.28" velocity="1.57" />
    </joint>
    <joint name="arm_3_to_arm_4" type="revolute">
        <parent link="arm_3" />
        <child link="arm_4" />
        <origin rpy="0 0 0" xyz="0.1 0 1.0" />
        <axis xyz="0 0 1" />
        <limit effort="20" lower="-6.28" upper="6.28" velocity="1.57" />
    </joint>
    <joint name="arm_4_to_arm_5" type="revolute">
        <parent link="arm_4" />
        <child link="arm_5" />
        <origin rpy="0 0 0" xyz="0 0 0" />
        <axis xyz="0 1 0" />
        <limit effort="20" lower="-6.28" upper="6.28" velocity="1.57" />
    </joint>
    <joint name="arm_5_to_arm_6" type="revolute">
        <parent link="arm_5" />
        <child link="arm_6" />
        <origin rpy="0 0 0" xyz="0 0 0" />
        <axis xyz="1 0 0" />
        <limit effort="20" lower="-6.28" upper="6.28" velocity="1.57" />
    </joint>
    <joint name="arm_6_to_end_effector" type="revolute">
        <parent link="arm_6" />
        <child link="end_effector" />
        <origin rpy="0 0 0" xyz="0 0 0" />
        <axis xyz="0 0 1" />
        <limit effort="0" lower="0" upper="0" velocity="0" />
    </joint>
    <transmission name="trans_base_to_its_part_1">
        <type>transmission_interface/SimpleTransmission</type>
        <joint name="base_to_its_part_1">
            <hardwareInterface>hardware_interface/PositionJointInterface</hardwareInterface>
        </joint>
        <actuator name="base_to_its_part_1_motor">
            <hardwareInterface>hardware_interface/PositionJointInterface</hardwareInterface>
            <mechanicalReduction>1</mechanicalReduction>
        </actuator>
    </transmission>
    <transmission name="trans_arm_1_to_arm_2">
        <type>transmission_interface/SimpleTransmission</type>
        <joint name="arm_1_to_arm_2">
            <hardwareInterface>hardware_interface/PositionJointInterface</hardwareInterface>
        </joint>
        <actuator name="arm_1_to_arm_2_motor">
            <hardwareInterface>hardware_interface/PositionJointInterface</hardwareInterface>
            <mechanicalReduction>1</mechanicalReduction>
        </actuator>
    </transmission>
    <transmission name="trans_arm_2_to_arm_3">
        <type>transmission_interface/SimpleTransmission</type>
        <joint name="arm_2_to_arm_3">
            <hardwareInterface>hardware_interface/PositionJointInterface</hardwareInterface>
        </joint>
        <actuator name="arm_2_to_arm_3_motor">
            <hardwareInterface>hardware_interface/PositionJointInterface</hardwareInterface>
            <mechanicalReduction>1</mechanicalReduction>
        </actuator>
    </transmission>
    <transmission name="trans_arm_3_to_arm_4">
        <type>transmission_interface/SimpleTransmission</type>
        <joint name="arm_3_to_arm_4">
            <hardwareInterface>hardware_interface/PositionJointInterface</hardwareInterface>
        </joint>
        <actuator name="arm_3_to_arm_4_motor">
            <hardwareInterface>hardware_interface/PositionJointInterface</hardwareInterface>
            <mechanicalReduction>1</mechanicalReduction>
        </actuator>
    </transmission>
    <transmission name="trans_arm_4_to_arm_5">
        <type>transmission_interface/SimpleTransmission</type>
        <joint name="arm_4_to_arm_5">
            <hardwareInterface>hardware_interface/PositionJointInterface</hardwareInterface>
        </joint>
        <actuator name="arm_4_to_arm_5_motor">
            <hardwareInterface>hardware_interface/PositionJointInterface</hardwareInterface>
            <mechanicalReduction>1</mechanicalReduction>
        </actuator>
    </transmission>
    <transmission name="trans_arm_5_to_arm_6">
        <type>transmission_interface/SimpleTransmission</type>
        <joint name="arm_5_to_arm_6">
            <hardwareInterface>hardware_interface/PositionJointInterface</hardwareInterface>
        </joint>
        <actuator name="arm_5_to_arm_6_motor">
            <hardwareInterface>hardware_interface/PositionJointInterface</hardwareInterface>
            <mechanicalReduction>1</mechanicalReduction>
        </actuator>
    </transmission>
    <transmission name="trans_arm_6_to_end_effector">
        <type>transmission_interface/SimpleTransmission</type>
        <joint name="arm_6_to_end_effector">
            <hardwareInterface>hardware_interface/PositionJointInterface</hardwareInterface>
        </joint>
        <actuator name="arm_6_to_end_effector_motor">
            <hardwareInterface>hardware_interface/PositionJointInterface</hardwareInterface>
            <mechanicalReduction>1</mechanicalReduction>
        </actuator>
    </transmission>
    <gazebo>
        <plugin name="gazebo_ros_control">
            <robotNamespace>/</robotNamespace>
        </plugin>
    </gazebo>
</robot>

